Workbook

Sheet Summary
B2: CBG Sector Summary Dashboard
B5: 1. State-wise Distribution — CBG Plants, Demand & Biomass Surplus (Pie Charts)
B6: State | C6: CBG Plants (Nos.) | D6: Plant Capacity (TPD) | E6: Current CBG Demand (TPD) | F6: Net Biomass Surplus (KTPA)
B7: Uttar Pradesh | C7: =SUMIFS('All States'!$E$4:$E$627,'All States'!$C$4:$C$627,"UP") -> 231 | D7: =SUMIFS('All States'!$F$4:$F$627,'All States'!$C$4:$C$627,"UP") -> 1771.08 | E7: =SUMIFS('All States'!$U$4:$U$627,'All States'!$C$4:$C$627,"UP") -> 114.3785 | F7: =SUMIFS('All States'!$M$4:$M$627,'All States'!$C$4:$C$627,"UP") -> 23156.965
B8: Maharashtra | C8: =SUMIFS('All States'!$E$4:$E$627,'All States'!$C$4:$C$627,"MH") -> 136 | D8: =SUMIFS('All States'!$F$4:$F$627,'All States'!$C$4:$C$627,"MH") -> 33158.331 | E8: =SUMIFS('All States'!$U$4:$U$627,'All States'!$C$4:$C$627,"MH") -> 115.34128 | F8: =SUMIFS('All States'!$M$4:$M$627,'All States'!$C$4:$C$627,"MH") -> 3804.11
B9: Madhya Pradesh | C9: =SUMIFS('All States'!$E$4:$E$627,'All States'!$C$4:$C$627,"MP") -> 98 | D9: =SUMIFS('All States'!$F$4:$F$627,'All States'!$C$4:$C$627,"MP") -> 16771.93 | E9: =SUMIFS('All States'!$U$4:$U$627,'All States'!$C$4:$C$627,"MP") -> 35.876302 | F9: =SUMIFS('All States'!$M$4:$M$627,'All States'!$C$4:$C$627,"MP") -> 17652.81
B10: Gujarat | C10: =SUMIFS('All States'!$E$4:$E$627,'All States'!$C$4:$C$627,"GJ") -> 102 | D10: =SUMIFS('All States'!$F$4:$F$627,'All States'!$C$4:$C$627,"GJ") -> 627.69 | E10: =SUMIFS('All States'!$U$4:$U$627,'All States'!$C$4:$C$627,"GJ") -> 122.57734 | F10: =SUMIFS('All States'!$M$4:$M$627,'All States'!$C$4:$C$627,"GJ") -> 2130.035
B11: Punjab | C11: =SUMIFS('All States'!$E$4:$E$627,'All States'!$C$4:$C$627,"PB") -> 82 | D11: =SUMIFS('All States'!$F$4:$F$627,'All States'!$C$4:$C$627,"PB") -> 1718.259 | E11: =SUMIFS('All States'!$U$4:$U$627,'All States'!$C$4:$C$627,"PB") -> 24.95712 | F11: =SUMIFS('All States'!$M$4:$M$627,'All States'!$C$4:$C$627,"PB") -> 13795.865
B12: Haryana | C12: =SUMIFS('All States'!$E$4:$E$627,'All States'!$C$4:$C$627,"HR") -> 68 | D12: =SUMIFS('All States'!$F$4:$F$627,'All States'!$C$4:$C$627,"HR") -> 525.1 | E12: =SUMIFS('All States'!$U$4:$U$627,'All States'!$C$4:$C$627,"HR") -> 52.515072 | F12: =SUMIFS('All States'!$M$4:$M$627,'All States'!$C$4:$C$627,"HR") -> 6881.1375
B13: Andhra Pradesh | C13: =SUMIFS('All States'!$E$4:$E$627,'All States'!$C$4:$C$627,"AP") -> 61 | D13: =SUMIFS('All States'!$F$4:$F$627,'All States'!$C$4:$C$627,"AP") -> 704.25 | E13: =SUMIFS('All States'!$U$4:$U$627,'All States'!$C$4:$C$627,"AP") -> 20.611828 | F13: =SUMIFS('All States'!$M$4:$M$627,'All States'!$C$4:$C$627,"AP") -> 4371.98
B14: Tamil Nadu | C14: =SUMIFS('All States'!$E$4:$E$627,'All States'!$C$4:$C$627,"TN") -> 53 | D14: =SUMIFS('All States'!$F$4:$F$627,'All States'!$C$4:$C$627,"TN") -> 544.94 | E14: =SUMIFS('All States'!$U$4:$U$627,'All States'!$C$4:$C$627,"TN") -> 40.129321 | F14: =SUMIFS('All States'!$M$4:$M$627,'All States'!$C$4:$C$627,"TN") -> 3933.86
B15: Karnataka | C15: =SUMIFS('All States'!$E$4:$E$627,'All States'!$C$4:$C$627,"KA") -> 37 | D15: =SUMIFS('All States'!$F$4:$F$627,'All States'!$C$4:$C$627,"KA") -> 201.028 | E15: =SUMIFS('All States'!$U$4:$U$627,'All States'!$C$4:$C$627,"KA") -> 45.800448 | F15: =SUMIFS('All States'!$M$4:$M$627,'All States'!$C$4:$C$627,"KA") -> 4502.22
B16: Rajasthan | C16: =SUMIFS('All States'!$E$4:$E$627,'All States'!$C$4:$C$627,"RJ") -> 47 | D16: =SUMIFS('All States'!$F$4:$F$627,'All States'!$C$4:$C$627,"RJ") -> 373.988 | E16: =SUMIFS('All States'!$U$4:$U$627,'All States'!$C$4:$C$627,"RJ") -> 42.829092 | F16: =SUMIFS('All States'!$M$4:$M$627,'All States'!$C$4:$C$627,"RJ") -> 6423.355
B17: Telangana | C17: =SUMIFS('All States'!$E$4:$E$627,'All States'!$C$4:$C$627,"TE") -> 48 | D17: =SUMIFS('All States'!$F$4:$F$627,'All States'!$C$4:$C$627,"TE") -> 456.18 | E17: =SUMIFS('All States'!$U$4:$U$627,'All States'!$C$4:$C$627,"TE") -> 21.346079 | F17: =SUMIFS('All States'!$M$4:$M$627,'All States'!$C$4:$C$627,"TE") -> 8397.135
B18: Bihar | C18: =SUMIFS('All States'!$E$4:$E$627,'All States'!$C$4:$C$627,"BR") -> 35 | D18: =SUMIFS('All States'!$F$4:$F$627,'All States'!$C$4:$C$627,"BR") -> 529.6 | E18: =SUMIFS('All States'!$U$4:$U$627,'All States'!$C$4:$C$627,"BR") -> 21.285847 | F18: =SUMIFS('All States'!$M$4:$M$627,'All States'!$C$4:$C$627,"BR") -> 9592.41
B19: Odisha | C19: =SUMIFS('All States'!$E$4:$E$627,'All States'!$C$4:$C$627,"OD") -> 26 | D19: =SUMIFS('All States'!$F$4:$F$627,'All States'!$C$4:$C$627,"OD") -> 194.6 | E19: =SUMIFS('All States'!$U$4:$U$627,'All States'!$C$4:$C$627,"OD") -> 14.076062 | F19: =SUMIFS('All States'!$M$4:$M$627,'All States'!$C$4:$C$627,"OD") -> 4139.52
B20: Chhattisgarh | C20: =SUMIFS('All States'!$E$4:$E$627,'All States'!$C$4:$C$627,"CG") -> 27 | D20: =SUMIFS('All States'!$F$4:$F$627,'All States'!$C$4:$C$627,"CG") -> 162.7 | E20: =SUMIFS('All States'!$U$4:$U$627,'All States'!$C$4:$C$627,"CG") -> 2.8055752 | F20: =SUMIFS('All States'!$M$4:$M$627,'All States'!$C$4:$C$627,"CG") -> -69.35
B21: Uttarakhand | C21: =SUMIFS('All States'!$E$4:$E$627,'All States'!$C$4:$C$627,"UK") -> 15 | D21: =SUMIFS('All States'!$F$4:$F$627,'All States'!$C$4:$C$627,"UK") -> 2960.32 | E21: =SUMIFS('All States'!$U$4:$U$627,'All States'!$C$4:$C$627,"UK") -> 5.9043379 | F21: =SUMIFS('All States'!$M$4:$M$627,'All States'!$C$4:$C$627,"UK") -> 598.54
B22: West Bengal | C22: =SUMIFS('All States'!$E$4:$E$627,'All States'!$C$4:$C$627,"WB") -> 14 | D22: =SUMIFS('All States'!$F$4:$F$627,'All States'!$C$4:$C$627,"WB") -> 73.9 | E22: =SUMIFS('All States'!$U$4:$U$627,'All States'!$C$4:$C$627,"WB") -> 12.092529 | F22: =SUMIFS('All States'!$M$4:$M$627,'All States'!$C$4:$C$627,"WB") -> -36.5
B23: Jharkhand | C23: =SUMIFS('All States'!$E$4:$E$627,'All States'!$C$4:$C$627,"JH") -> 5 | D23: =SUMIFS('All States'!$F$4:$F$627,'All States'!$C$4:$C$627,"JH") -> 161 | E23: =SUMIFS('All States'!$U$4:$U$627,'All States'!$C$4:$C$627,"JH") -> 14.505604 | F23: =SUMIFS('All States'!$M$4:$M$627,'All States'!$C$4:$C$627,"JH") -> 1727.88
B24: Delhi | C24: =SUMIFS('All States'!$E$4:$E$627,'All States'!$C$4:$C$627,"DL") -> 8 | D24: =SUMIFS('All States'!$F$4:$F$627,'All States'!$C$4:$C$627,"DL") -> 50.3 | E24: =SUMIFS('All States'!$U$4:$U$627,'All States'!$C$4:$C$627,"DL") -> 54.279529 | F24: =SUMIFS('All States'!$M$4:$M$627,'All States'!$C$4:$C$627,"DL") -> 0
B25: Assam | C25: =SUMIFS('All States'!$E$4:$E$627,'All States'!$C$4:$C$627,"AS") -> 6 | D25: =SUMIFS('All States'!$F$4:$F$627,'All States'!$C$4:$C$627,"AS") -> 63.5 | E25: =SUMIFS('All States'!$U$4:$U$627,'All States'!$C$4:$C$627,"AS") -> 3.1972683 | F25: =SUMIFS('All States'!$M$4:$M$627,'All States'!$C$4:$C$627,"AS") -> 2312.685
B26: Kerala | C26: =SUMIFS('All States'!$E$4:$E$627,'All States'!$C$4:$C$627,"KL") -> 5 | D26: =SUMIFS('All States'!$F$4:$F$627,'All States'!$C$4:$C$627,"KL") -> 29.8 | E26: =SUMIFS('All States'!$U$4:$U$627,'All States'!$C$4:$C$627,"KL") -> 20.025327 | F26: =SUMIFS('All States'!$M$4:$M$627,'All States'!$C$4:$C$627,"KL") -> 216.72
B27: Chandigarh | C27: =SUMIFS('All States'!$E$4:$E$627,'All States'!$C$4:$C$627,"CH") -> 1 | D27: =SUMIFS('All States'!$F$4:$F$627,'All States'!$C$4:$C$627,"CH") -> 20 | E27: =SUMIFS('All States'!$U$4:$U$627,'All States'!$C$4:$C$627,"CH") -> 3.1210416 | F27: =SUMIFS('All States'!$M$4:$M$627,'All States'!$C$4:$C$627,"CH") -> 1.35
B28: Goa | C28: =SUMIFS('All States'!$E$4:$E$627,'All States'!$C$4:$C$627,"GA") -> 1 | D28: =SUMIFS('All States'!$F$4:$F$627,'All States'!$C$4:$C$627,"GA") -> 0.5 | E28: =SUMIFS('All States'!$U$4:$U$627,'All States'!$C$4:$C$627,"GA") -> 1.4078541 | F28: =SUMIFS('All States'!$M$4:$M$627,'All States'!$C$4:$C$627,"GA") -> 21.39
B29: Himachal Pradesh | C29: =SUMIFS('All States'!$E$4:$E$627,'All States'!$C$4:$C$627,"HP") -> 5 | D29: =SUMIFS('All States'!$F$4:$F$627,'All States'!$C$4:$C$627,"HP") -> 37.15 | E29: =SUMIFS('All States'!$U$4:$U$627,'All States'!$C$4:$C$627,"HP") -> 2.5497852 | F29: =SUMIFS('All States'!$M$4:$M$627,'All States'!$C$4:$C$627,"HP") -> 717.36
B30: Jammu & Kashmir | C30: =SUMIFS('All States'!$E$4:$E$627,'All States'!$C$4:$C$627,"JK") -> 1 | D30: =SUMIFS('All States'!$F$4:$F$627,'All States'!$C$4:$C$627,"JK") -> 1 | E30: =SUMIFS('All States'!$U$4:$U$627,'All States'!$C$4:$C$627,"JK") -> 0.375 | F30: =SUMIFS('All States'!$M$4:$M$627,'All States'!$C$4:$C$627,"JK") -> 843.645
B31: Source: All States sheet (624 district rows aggregated to 24 states), live SUMIFS. Demand = Current CBG Demand (TPD) at 3% penetration of district CNG offtake plus PNG household demand (Control!B4, B5, B8). Surplus = Total Net Surplus after feedstock used by existing plants (KTPA). Charts are placed to the right of this table.
B34: 2. Top 5 Entities
B35: (a) Top 5 Entities by Number of CBG Plants
B36: Rank | C36: Entity | D36: No. of CBG Plants
B37: 1 | C37: Reliance Industries Limited | D37: =COUNTIF('CBG Plants'!$K$2:$K$1216,$C37&"*") -> 50
B38: 2 | C38: Bio-WMS Private Limited | D38: =COUNTIF('CBG Plants'!$K$2:$K$1216,$C38&"*") -> 13
B39: 3 | C39: Mann Residency Pvt. Ltd. | D39: =COUNTIF('CBG Plants'!$K$2:$K$1216,$C39&"*") -> 13
B40: 4 | C40: EverEnviro Resource Management Private Limited | D40: =COUNTIF('CBG Plants'!$K$2:$K$1216,$C40&"*") -> 11
B41: 5 | C41: IOC GPS RENEWABLES PRIVATE LIMITED | D41: =COUNTIF('CBG Plants'!$K$2:$K$1216,$C41&"*") -> 10
B43: (b) Top 5 Entities by Total Plant Production Capacity (TPD)
B44: Rank | C44: Entity | D44: Total Capacity (TPD)
B45: 1 | C45: Reliance Industries Limited | D45: =SUMIF('CBG Plants'!$K$2:$K$1216,$C45&"*",'CBG Plants'!$AA$2:$AA$1216) -> 1056.2
B46: 2 | C46: ZENECO WASTECX PRIVATE LIMITED | D46: =SUMIF('CBG Plants'!$K$2:$K$1216,$C46&"*",'CBG Plants'!$AA$2:$AA$1216) -> 422
...

Sheet Control
B3: Parameters | C3: UoM | H3: Napier Grass | I3: Maize Stover | J3: Paddy Straw | K3: Cane Trash | L3: Press Mud | M3: OF MSW | N3: Thick Slop | O3: Soya Trash
B4: Net CBG Demand | C4: TPD | D4: 3 | G4: Yeild | H4: 0.04089164 | I4: 0.10008581 | J4: 0.12470724 | K4: 0.1063785 | L4: 0.040390117 | M4: 0.038243549 | N4: 0.039213706 | O4: 0.10743667
B5: Net Biomass Surplus | C5: KTPA | D5: 50 | G5: Moisture | H5: 0.75 | I5: 0.15 | J5: 0.2 | K5: 0.12 | L5: 0.7 | M5: 0.75 | N5: 0.8 | O5: 0.2
B6: Straws (PS, CT, MS) | C6: % | E6: =SUM(J7,K7,I7) -> 0 | G6: ODM | H6: 0.25 | I6: 0.85 | J6: 0.8 | K6: 0.88 | L6: 0.3 | M6: 0.25 | N6: 0.2 | O6: 0.8
B7: Industrials (PM, OFMSW, TS) | C7: % | E7: =SUM(L7,M7,N7) -> 0 | G7: RM Blend
B8: Energy Crops | C8: % | E8: =SUM(H7) -> 0
B9: Net Est Demand 5Y | D9: 10
B10: Nearest Pipeline | C10: km | D10: 3000
B11: Distance from large city | C11: km | D11: 0

Sheet Top District
B2: Sr. | C2: State | D2: District | E2: Net CBG Demand (TPD) | F2: Raw Material (KTPA) | G2: Nearest Pipeline (km) | H2: Distance from Large city | I2: Est Net CBG Demand - 5Y
B3: 1 | C3: {=_xlfn._xlws.FILTER('All States (2)'!C4:C1000,('All States (2)'!AE4:AE1000="Y")*('All States (2)'!AF4:AF1000="Y")*('All States (2)'!AG4:AG1000="Y"),"No matching data")} -> GJ | D3: {=_xlfn._xlws.FILTER('All States (2)'!D4:D1000,('All States (2)'!AE4:AE1000="Y")*('All States (2)'!AF4:AF1000="Y")*('All States (2)'!AG4:AG1000="Y"),"No matching data")} -> Gandhinagar | E3: {=_xlfn._xlws.FILTER('All States (2)'!R4:R1000,('All States (2)'!AE4:AE1000="Y")*('All States (2)'!AF4:AF1000="Y")*('All States (2)'!AG4:AG1000="Y"),"No matching data")} -> 3.8257156 | F3: {=_xlfn._xlws.FILTER('All States (2)'!M4:M1000,('All States (2)'!AE4:AE1000="Y")*('All States (2)'!AF4:AF1000="Y")*('All States (2)'!AG4:AG1000="Y"),"No matching data")} -> 51.81 | G3: {=_xlfn._xlws.FILTER('All States (2)'!AB4:AB1000,('All States (2)'!AE4:AE1000="Y")*('All States (2)'!AF4:AF1000="Y")*('All States (2)'!AG4:AG1000="Y"),"No matching data")} -> 9.8 | I3: {=_xlfn._xlws.FILTER('All States (2)'!X4:X1000,('All States (2)'!AE4:AE1000="Y")*('All States (2)'!AF4:AF1000="Y")*('All States (2)'!AG4:AG1000="Y"),"No matching data")} -> 31.7774
B4: 2 | C4: GJ | D4: Mahesana | E4: 6.8257156 | F4: 96.255 | G4: 9.8 | I4: 34.7774
B5: 3 | C5: GJ | D5: Rajkot | E5: 4.4283409 | F5: 177.75 | G5: 189.3 | I5: 51.5336
B6: 4 | C6: GJ | D6: Valsad | E6: 14.549574 | F6: 79.38 | G6: 134.2 | I6: 73.9657
B7: 5 | C7: MH | D7: Ahilyanagar | E7: 5.6293159 | F7: 358.665 | G7: 84.4 | I7: 28.5931
B8: 6 | C8: MH | D8: Chhatrapati Sambhajinagar | E8: 5.6293159 | F8: 434.325 | G8: 189.2 | I8: 28.5931
B9: 7 | C9: HR | D9: Faridabad | E9: 4.4662171 | F9: 59.295 | G9: 48.3 | I9: 22.7334
B10: 8 | C10: HR | D10: Gurugram | E10: 4.8764329 | F10: 63.1925 | G10: 13.5 | I10: 37.9087
B11: 9 | C11: HR | D11: Rewari | E11: 3.6887038 | F11: 68.16 | G11: 28.2 | I11: 18.7271
B12: 10 | C12: TN | D12: Thiruvallur | E12: 3.3277882 | F12: 109.34 | G12: 40.4 | I12: 16.8913
B13: 11
B14: 12
B15: 13
B16: 14
B17: 15
B18: 16
B19: 17
B20: 18
B21: 19
B22: 20
B23: 21
B24: 22
... B59: 57

Sheet Top GAs
B2: GA ID | C2: State | D2: Districts | E2: Current Net CBG Demand in GA (TPD) | F2: Raw Material (KTPA) | G2: Pipeline Availability (km) | H2: Distance from Large city | I2: Est Net CBG Demand - 5Y
B3: {=_xlfn._xlws.FILTER( GAs!D4:D1000, (GAs!AH4:AH1000="Y")* (GAs!AI4:AI1000="Y")* (GAs!AJ4:AJ1000="Y"), "No matching data" )} -> 98.10 | C3: {=_xlfn._xlws.FILTER( GAs!C4:C1000, (GAs!AH4:AH1000="Y")* (GAs!AI4:AI1000="Y")* (GAs!AJ4:AJ1000="Y"), "No matching data" )} -> Gujarat | D3: {=_xlfn._xlws.FILTER( GAs!E4:E1000, (GAs!AH4:AH1000="Y")* (GAs!AI4:AI1000="Y")* (GAs!AJ4:AJ1000="Y"), "No matching data" )} -> Valsad | E3: {=_xlfn._xlws.FILTER( GAs!U4:U1000, (GAs!AH4:AH1000="Y")* (GAs!AI4:AI1000="Y")* (GAs!AJ4:AJ1000="Y"), "No matching data" )} -> 14.549574 | F3: {=_xlfn._xlws.FILTER( GAs!P4:P1000, (GAs!AH4:AH1000="Y")* (GAs!AI4:AI1000="Y")* (GAs!AJ4:AJ1000="Y"), "No matching data" )} -> 79.38 | G3: {=_xlfn._xlws.FILTER( GAs!AJ4:AJ1000, (GAs!AH4:AH1000="Y")* (GAs!AI4:AI1000="Y")* (GAs!AJ4:AJ1000="Y"), "No matching data" )} -> Y | I3: {=_xlfn._xlws.FILTER( GAs!AA4:AA1000, (GAs!AH4:AH1000="Y")* (GAs!AI4:AI1000="Y")* (GAs!AJ4:AJ1000="Y"), "No matching data" )} -> 71.388755
B4: 95.03 | C4: Haryana | D4: Gurugram-1 | E4: 4.8764329 | F4: 63.1925 | G4: Y | I4: 39.525597
B5: 98.13 | C5: Haryana | D5: Gurugram-2 | E5: 4.8764329 | F5: 63.1925 | G5: Y | I5: 39.525597
B6: 95.01 | C6: Haryana | D6: Faridabad-2 | E6: 4.4662171 | F6: 59.295 | G6: Y | I6: 21.350597
B7: 95.02 | C7: Haryana | D7: Faridabad-1 | E7: 4.4662171 | F7: 59.295 | G7: Y | I7: 21.350597
B8: 98.06 | C8: Gujarat | D8: Rajkot | E8: 4.4283409 | F8: 177.75 | G8: Y | I8: 51.533613
B9: 6.15 | C9: Haryana | D9: Rewari District | E9: 3.6887038 | F9: 68.16 | G9: Y | I9: 16.899109
B10: 9.26 | C10: Karnataka | D10: Ballari & Gadag Districts | E10: 3.6433884 | F10: 485.85 | G10: Y | I10: 17.651988
B11: 99.05 | C11: Maharashtra | D11: Pune City including Pimpri - Chinchwad & adjoining contiguous areas Hinjewadi, Chakan, Talegaon | E11: 19.753372 | F11: 224.76 | G11: Y | I11: 77.765568
B12: 9.39 | C12: Maharashtra & Gujarat | D12: Valsad (EAAA), Dhule & Nashik Districts | E12: 13.495615 | F12: 955.2 | G12: Y | I12: 118.59969

Sheet All States (2)
E2: Competition | M2: Crop Surplus | R2: CGD Demand | Z2: Pipeline
B3: Sr | C3: State | D3: District | E3: CBG Plant Nos. | F3: Total CBG Plant Capacity (TPD) | G3: Functional & Completed (Nos) | H3: Under Construction (Nos.) | I3: Yet to Start (Nos.) | J3: P1 | K3: P2 | L3: P3 | M3: Total Net Surplus (KTPA) | N3: Total Gross Surplus (KTPA) | O3: Whaet Surplus | P3: Rice Surplus | Q3: Maize Surplus | R3: Net TPD CBG | S3: Gross TPD CNG | T3: Current CNG Stations | U3: Current CBG Demand @ 3% (TPD) | V3: Current PNG HH | W3: Est. 5Y CNG Stations | X3: Future Net CBG Demand @ 5% (TPD) | Y3: Est. 5Y PNG HH | Z3: Type | AA3: Name of Pipeline | AB3: Distance to Pipeline Route (Km, approx.) | AC3: MMSCMD Capacity | AD3: Feedstock Used by Existing Plants (TPD) | AE3: Demand | AF3: Raw Material | AG3: Nearest Pipeline | AH3: Distance from Large city | AI3: Est Net CBG Demand - 5Y | AK3: Gov Support
B4: 4 | C4: TE | D4: Hyderabad | E4: =SUM(G4:I4) -> 2 | F4: =SUMIFS('CBG Plants'!N:N,'CBG Plants'!F:F,D4,'CBG Plants'!L:L,"Completed") +SUMIFS('CBG Plants'!N:N,'CBG Plants'!F:F,D4,'CBG Plants'!L:L,"Functional")+SUMIFS('CBG Plants'!N:N,'CBG Plants'!F:F,D4,'CBG Plants'!L:L,"Under Construction")+SUMIFS('CBG Plants'!N:N,'CBG Plants'!F:F,D4,'CBG Plants'!L:L,"Yet to start construction") -> 5 | G4: =COUNTIFS('CBG Plants'!F:F,D4,'CBG Plants'!L:L,"Completed") +COUNTIFS('CBG Plants'!F:F,D4,'CBG Plants'!L:L,"Functional") -> 2 | H4: =COUNTIFS('CBG Plants'!F:F,D4,'CBG Plants'!L:L,"Under Construction") -> 0 | I4: =COUNTIFS('CBG Plants'!F:F,D4,'CBG Plants'!L:L,"Yet to start construction") -> 0 | J4: AMBERPET -HYDERABAD | K4: NAGOLE -HYDERDABAD | M4: =IFERROR(N4-(AD4*365/1000),"") -> 0 | N4: =SUM(O4:Q4) -> 0 | R4: =IFERROR(U4-F4,"") -> 4.7826125 | S4: =IFERROR(T4*Assumptions!$C$4,"") -> 245 | T4: 98 | U4: =IFERROR(S4*Assumptions!$C$5,"")+IFERROR(V4*Assumptions!$C$8*Assumptions!$C$5,"") -> 9.7826125 | V4: 242051 | W4: =IFERROR(ROUND(T4*(1+Assumptions!$C$7)^5,0),"") -> 299 | X4: =IFERROR(ROUND(W4*Assumptions!$C$4*Assumptions!$C$6,4),"")+IFERROR(ROUND(Y4*Assumptions!$C$8*Assumptions!$C$6,4),"") - F4 -> 44.7479 | Y4: =IFERROR(ROUND(V4*(1+Assumptions!$C$7)^5,0),"") -> 738681 | Z4: Operational Common Carrier | AA4: Kakinada-Hyderabad-Uran-Ahmedabad (East West Pipeline) | AB4: 0.6 | AC4: 85 | AD4: 0 | AE4: =IF(R4="","",IF(R4>=Control!$D$4,"Y","N")) -> Y | AF4: =IF(S4="","",IF(M4>=Control!$D$5,"Y","N")) -> N | AG4: =IF(T4="","",IF(AB4<=Control!$D$10,"Y","N")) -> Y | AI4: =IF(X4="","",IF(X4>=Control!$D$9,"Y","N")) -> Y | AK4: =IFERROR(INDEX(Assumptions!$D$92:$D$115,MATCH(C4,Assumptions!$B$92:$B$115,0)),"Low") -> Low
B5: 29 | C5: TE | D5: Suryapet | E5: =SUM(G5:I5) -> 1 | F5: =SUMIFS('CBG Plants'!N:N,'CBG Plants'!F:F,D5,'CBG Plants'!L:L,"Completed") +SUMIFS('CBG Plants'!N:N,'CBG Plants'!F:F,D5,'CBG Plants'!L:L,"Functional")+SUMIFS('CBG Plants'!N:N,'CBG Plants'!F:F,D5,'CBG Plants'!L:L,"Under Construction")+SUMIFS('CBG Plants'!N:N,'CBG Plants'!F:F,D5,'CBG Plants'!L:L,"Yet to start construction") -> 0 | G5: =COUNTIFS('CBG Plants'!F:F,D5,'CBG Plants'!L:L,"Completed") +COUNTIFS('CBG Plants'!F:F,D5,'CBG Plants'!L:L,"Functional") -> 0 | H5: =COUNTIFS('CBG Plants'!F:F,D5,'CBG Plants'!L:L,"Under Construction") -> 0 | I5: =COUNTIFS('CBG Plants'!F:F,D5,'CBG Plants'!L:L,"Yet to start construction") -> 1 | J5: SAMYUKTHA POWER PRIVATE LIMITED | M5: =IFERROR(N5-(AD5*365/1000),"") -> 557.34 | N5: =SUM(O5:Q5) -> 557.34 | O5: 0 | P5: 555.24 | Q5: 2.1 | R5: =IFERROR(U5-F5,"") -> 0.54627585 | S5: =IFERROR(T5*Assumptions!$C$4,"") -> 17.5 | T5: 7 | U5: =IFERROR(S5*Assumptions!$C$5,"")+IFERROR(V5*Assumptions!$C$8*Assumptions!$C$5,"") -> 0.54627585 | V5: 2117 | W5: =IFERROR(ROUND(T5*(1+Assumptions!$C$7)^5,0),"") -> 21 | X5: =IFERROR(ROUND(W5*Assumptions!$C$4*Assumptions!$C$6,4),"")+IFERROR(ROUND(Y5*Assumptions!$C$8*Assumptions!$C$6,4),"") - F5 -> 2.7332 | Y5: =IFERROR(ROUND(V5*(1+Assumptions!$C$7)^5,0),"") -> 6461 | Z5: Operational Common Carrier | AA5: Kakinada-Hyderabad-Uran-Ahmedabad (East West Pipeline) | AB5: 18.8 | AC5: 85 | AD5: 0 | AE5: =IF(R5="","",IF(R5>=Control!$D$4,"Y","N")) -> N | AF5: =IF(S5="","",IF(M5>=Control!$D$5,"Y","N")) -> Y | AG5: =IF(T5="","",IF(AB5<=Control!$D$10,"Y","N")) -> Y | AI5: =IF(X5="","",IF(X5>=Control!$D$9,"Y","N")) -> N | AK5: =IFERROR(INDEX(Assumptions!$D$92:$D$115,MATCH(C5,Assumptions!$B$92:$B$115,0)),"Low") -> Low
B6: 2 | C6: TE | D6: Bhadradri Kothagudem | E6: =SUM(G6:I6) -> 0 | F6: =SUMIFS('CBG Plants'!N:N,'CBG Plants'!F:F,D6,'CBG Plants'!L:L,"Completed") +SUMIFS('CBG Plants'!N:N,'CBG Plants'!F:F,D6,'CBG Plants'!L:L,"Functional")+SUMIFS('CBG Plants'!N:N,'CBG Plants'!F:F,D6,'CBG Plants'!L:L,"Under Construction")+SUMIFS('CBG Plants'!N:N,'CBG Plants'!F:F,D6,'CBG Plants'!L:L,"Yet to start construction") -> 0 | G6: =COUNTIFS('CBG Plants'!F:F,D6,'CBG Plants'!L:L,"Completed") +COUNTIFS('CBG Plants'!F:F,D6,'CBG Plants'!L:L,"Functional") -> 0 | H6: =COUNTIFS('CBG Plants'!F:F,D6,'CBG Plants'!L:L,"Under Construction") -> 0 | I6: =COUNTIFS('CBG Plants'!F:F,D6,'CBG Plants'!L:L,"Yet to start construction") -> 0 | M6: =IFERROR(N6-(AD6*365/1000),"") -> 228.06 | N6: =SUM(O6:Q6) -> 228.06 | O6: 0 | P6: 131.46 | Q6: 96.6 | R6: =IFERROR(U6-F6,"") -> 0.5361354 | S6: =IFERROR(T6*Assumptions!$C$4,"") -> 17.5 | T6: 7 | U6: =IFERROR(S6*Assumptions!$C$5,"")+IFERROR(V6*Assumptions!$C$8*Assumptions!$C$5,"") -> 0.5361354 | V6: 1108 | W6: =IFERROR(ROUND(T6*(1+Assumptions!$C$7)^5,0),"") -> 21 | X6: =IFERROR(ROUND(W6*Assumptions!$C$4*Assumptions!$C$6,4),"")+IFERROR(ROUND(Y6*Assumptions!$C$8*Assumptions!$C$6,4),"") - F6 -> 2.6816 | Y6: =IFERROR(ROUND(V6*(1+Assumptions!$C$7)^5,0),"") -> 3381 | Z6: Operational Common Carrier | AA6: Kakinada-Hyderabad-Uran-Ahmedabad (East West Pipeline) | AB6: 57.6 | AC6: 85 | AD6: 0 | AE6: =IF(R6="","",IF(R6>=Control!$D$4,"Y","N")) -> N | AF6: =IF(S6="","",IF(M6>=Control!$D$5,"Y","N")) -> Y | AG6: =IF(T6="","",IF(AB6<=Control!$D$10,"Y","N")) -> Y | AI6: =IF(X6="","",IF(X6>=Control!$D$9,"Y","N")) -> N | AK6: =IFERROR(INDEX(Assumptions!$D$92:$D$115,MATCH(C6,Assumptions!$B$92:$B$115,0)),"Low") -> Low
B7: 9 | C7: TE | D7: Kamareddy | E7: =SUM(G7:I7) -> 0 | F7: =SUMIFS('CBG Plants'!N:N,'CBG Plants'!F:F,D7,'CBG Plants'!L:L,"Completed") +SUMIFS('CBG Plants'!N:N,'CBG Plants'!F:F,D7,'CBG Plants'!L:L,"Functional")+SUMIFS('CBG Plants'!N:N,'CBG Plants'!F:F,D7,'CBG Plants'!L:L,"Under Construction")+SUMIFS('CBG Plants'!N:N,'CBG Plants'!F:F,D7,'CBG Plants'!L:L,"Yet to start construction") -> 0 | G7: =COUNTIFS('CBG Plants'!F:F,D7,'CBG Plants'!L:L,"Completed") +COUNTIFS('CBG Plants'!F:F,D7,'CBG Plants'!L:L,"Functional") -> 0 | H7: =COUNTIFS('CBG Plants'!F:F,D7,'CBG Plants'!L:L,"Under Construction") -> 0 | I7: =COUNTIFS('CBG Plants'!F:F,D7,'CBG Plants'!L:L,"Yet to start construction") -> 0 | J7: BLUELEO-01 | K7: Blue leo by bia green pvt ltd | M7: =IFERROR(N7-(AD7*365/1000),"") -> 507.6 | N7: =SUM(O7:Q7) -> 507.6 | O7: 0.45 | P7: 388.5 | Q7: 118.65 | R7: =IFERROR(U7-F7,"") -> 0.375 | S7: =IFERROR(T7*Assumptions!$C$4,"") -> 12.5 | T7: 5 | U7: =IFERROR(S7*Assumptions!$C$5,"")+IFERROR(V7*Assumptions!$C$8*Assumptions!$C$5,"") -> 0.375 | V7: 0 | W7: =IFERROR(ROUND(T7*(1+Assumptions!$C$7)^5,0),"") -> 15 | X7: =IFERROR(ROUND(W7*Assumptions!$C$4*Assumptions!$C$6,4),"")+IFERROR(ROUND(Y7*Assumptions!$C$8*Assumptions!$C$6,4),"") - F7 -> 1.875 | Y7: =IFERROR(ROUND(V7*(1+Assumptions!$C$7)^5,0),"") -> 0 | Z7: Operational Common Carrier | AA7: Kakinada-Hyderabad-Uran-Ahmedabad (East West Pipeline) | AB7: 87.9 | AC7: 85 | AD7: 0 | AE7: =IF(R7="","",IF(R7>=Control!$D$4,"Y","N")) -> N | AF7: =IF(S7="","",IF(M7>=Control!$D$5,"Y","N")) -> Y | AG7: =IF(T7="","",IF(AB7<=Control!$D$10,"Y","N")) -> Y | AI7: =IF(X7="","",IF(X7>=Control!$D$9,"Y","N")) -> N | AK7: =IFERROR(INDEX(Assumptions!$D$92:$D$115,MATCH(C7,Assumptions!$B$92:$B$115,0)),"Low") -> Low
B8: 12 | C8: TE | D8: Kumuram Bheem Asifabad | E8: =SUM(G8:I8) -> 0 | F8: =SUMIFS('CBG Plants'!N:N,'CBG Plants'!F:F,D8,'CBG Plants'!L:L,"Completed") +SUMIFS('CBG Plants'!N:N,'CBG Plants'!F:F,D8,'CBG Plants'!L:L,"Functional")+SUMIFS('CBG Plants'!N:N,'CBG Plants'!F:F,D8,'CBG Plants'!L:L,"Under Construction")+SUMIFS('CBG Plants'!N:N,'CBG Plants'!F:F,D8,'CBG Plants'!L:L,"Yet to start construction") -> 0 | G8: =COUNTIFS('CBG Plants'!F:F,D8,'CBG Plants'!L:L,"Completed") +COUNTIFS('CBG Plants'!F:F,D8,'CBG Plants'!L:L,"Functional") -> 0 | H8: =COUNTIFS('CBG Plants'!F:F,D8,'CBG Plants'!L:L,"Under Construction") -> 0 | I8: =COUNTIFS('CBG Plants'!F:F,D8,'CBG Plants'!L:L,"Yet to start construction") -> 0 | M8: =IFERROR(N8-(AD8*365/1000),"") -> 43.92 | N8: =SUM(O8:Q8) -> 43.92 | O8: 0.45 | P8: 38.22 | Q8: 5.25 | R8: =IFERROR(U8-F8,"") -> 0.375 | S8: =IFERROR(T8*Assumptions!$C$4,"") -> 12.5 | T8: 5 | U8: =IFERROR(S8*Assumptions!$C$5,"")+IFERROR(V8*Assumptions!$C$8*Assumptions!$C$5,"") -> 0.375 | V8: 0 | W8: =IFERROR(ROUND(T8*(1+Assumptions!$C$7)^5,0),"") -> 15 | X8: =IFERROR(ROUND(W8*Assumptions!$C$4*Assumptions!$C$6,4),"")+IFERROR(ROUND(Y8*Assumptions!$C$8*Assumptions!$C$6,4),"") - F8 -> 1.875 | Y8: =IFERROR(ROUND(V8*(1+Assumptions!$C$7)^5,0),"") -> 0 | Z8: Operational Common Carrier | AA8: Kakinada-Hyderabad-Uran-Ahmedabad (East West Pipeline) | AB8: 228 | AC8: 85 | AD8: 0 | AE8: =IF(R8="","",IF(R8>=Control!$D$4,"Y","N")) -> N | AF8: =IF(S8="","",IF(M8>=Control!$D$5,"Y","N")) -> N | AG8: =IF(T8="","",IF(AB8<=Control!$D$10,"Y","N")) -> Y | AI8: =IF(X8="","",IF(X8>=Control!$D$9,"Y","N")) -> N | AK8: =IFERROR(INDEX(Assumptions!$D$92:$D$115,MATCH(C8,Assumptions!$B$92:$B$115,0)),"Low") -> Low
B9: 22 | C9: TE | D9: Nirmal | E9: =SUM(G9:I9) -> 0 | F9: =SUMIFS('CBG Plants'!N:N,'CBG Plants'!F:F,D9,'CBG Plants'!L:L,"Completed") +SUMIFS('CBG Plants'!N:N,'CBG Plants'!F:F,D9,'CBG Plants'!L:L,"Functional")+SUMIFS('CBG Plants'!N:N,'CBG Plants'!F:F,D9,'CBG Plants'!L:L,"Under Construction")+SUMIFS('CBG Plants'!N:N,'CBG Plants'!F:F,D9,'CBG Plants'!L:L,"Yet to start construction") -> 0 | G9: =COUNTIFS('CBG Plants'!F:F,D9,'CBG Plants'!L:L,"Completed") +COUNTIFS('CBG Plants'!F:F,D9,'CBG Plants'!L:L,"Functional") -> 0 | H9: =COUNTIFS('CBG Plants'!F:F,D9,'CBG Plants'!L:L,"Under Construction") -> 0 | I9: =COUNTIFS('CBG Plants'!F:F,D9,'CBG Plants'!L:L,"Yet to start construction") -> 0 | M9: =IFERROR(N9-(AD9*365/1000),"") -> 336.315 | N9: =SUM(O9:Q9) -> 336.315 | O9: 0 | P9: 147.84 | Q9: 188.475 | R9: =IFERROR(U9-F9,"") -> 0.375 | S9: =IFERROR(T9*Assumptions!$C$4,"") -> 12.5 | T9: 5 | U9: =IFERROR(S9*Assumptions!$C$5,"")+IFERROR(V9*Assumptions!$C$8*Assumptions!$C$5,"") -> 0.375 | V9: 0 | W9: =IFERROR(ROUND(T9*(1+Assumptions!$C$7)^5,0),"") -> 15 | X9: =IFERROR(ROUND(W9*Assumptions!$C$4*Assumptions!$C$6,4),"")+IFERROR(ROUND(Y9*Assumptions!$C$8*Assumptions!$C$6,4),"") - F9 -> 1.875 | Y9: =IFERROR(ROUND(V9*(1+Assumptions!$C$7)^5,0),"") -> 0 | Z9: Operational Common Carrier | AA9: Kakinada-Hyderabad-Uran-Ahmedabad (East West Pipeline) | AB9: 179.2 | AC9: 85 | AD9: 0 | AE9: =IF(R9="","",IF(R9>=Control!$D$4,"Y","N")) -> N | AF9: =IF(S9="","",IF(M9>=Control!$D$5,"Y","N")) -> Y | AG9: =IF(T9="","",IF(AB9<=Control!$D$10,"Y","N")) -> Y | AI9: =IF(X9="","",IF(X9>=Control!$D$9,"Y","N")) -> N | AK9: =IFERROR(INDEX(Assumptions!$D$92:$D$115,MATCH(C9,Assumptions!$B$92:$B$115,0)),"Low") -> Low
B10: 13 | C10: TE | D10: Mahabubabad | E10: =SUM(G10:I10) -> 0 | F10: =SUMIFS('CBG Plants'!N:N,'CBG Plants'!F:F,D10,'CBG Plants'!L:L,"Completed") +SUMIFS('CBG Plants'!N:N,'CBG Plants'!F:F,D10,'CBG Plants'!L:L,"Functional")+SUMIFS('CBG Plants'!N:N,'CBG Plants'!F:F,D10,'CBG Plants'!L:L,"Under Construction")+SUMIFS('CBG Plants'!N:N,'CBG Plants'!F:F,D10,'CBG Plants'!L:L,"Yet to start construction") -> 0 | G10: =COUNTIFS('CBG Plants'!F:F,D10,'CBG Plants'!L:L,"Completed") +COUNTIFS('CBG Plants'!F:F,D10,'CBG Plants'!L:L,"Functional") -> 0 | H10: =COUNTIFS('CBG Plants'!F:F,D10,'CBG Plants'!L:L,"Under Construction") -> 0 | I10: =COUNTIFS('CBG Plants'!F:F,D10,'CBG Plants'!L:L,"Yet to start construction") -> 0 | J10: USHODAYAM BIOENERGY PRIVATE LIMITED | K10: Solika Energy - Udithyal | M10: =IFERROR(N10-(AD10*365/1000),"") -> 281.235 | N10: =SUM(O10:Q10) -> 303.135 | O10: 0 | P10: 188.16 | Q10: 114.975 | R10: =IFERROR(U10-F10,"") -> 0.31546695 | S10: =IFERROR(T10*Assumptions!$C$4,"") -> 10 | T10: 4 | U10: =IFERROR(S10*Assumptions!$C$5,"")+IFERROR(V10*Assumptions!$C$8*Assumptions!$C$5,"") -> 0.31546695 | V10: 1539 | W10: =IFERROR(ROUND(T10*(1+Assumptions!$C$7)^5,0),"") -> 12 | X10: =IFERROR(ROUND(W10*Assumptions!$C$4*Assumptions!$C$6,4),"")+IFERROR(ROUND(Y10*Assumptions!$C$8*Assumptions!$C$6,4),"") - F10 -> 1.5787 | Y10: =IFERROR(ROUND(V10*(1+Assumptions!$C$7)^5,0),"") -> 4697 | Z10: Operational Common Carrier | AA10: Kakinada-Hyderabad-Uran-Ahmedabad (East West Pipeline) | AB10: 49.1 | AC10: 85 | AD10: 60 | AE10: =IF(R10="","",IF(R10>=Control!$D$4,"Y","N")) -> N | AF10: =IF(S10="","",IF(M10>=Control!$D$5,"Y","N")) -> Y | AG10: =IF(T10="","",IF(AB10<=Control!$D$10,"Y","N")) -> Y | AI10: =IF(X10="","",IF(X10>=Control!$D$9,"Y","N")) -> N | AK10: =IFERROR(INDEX(Assumptions!$D$92:$D$115,MATCH(C10,Assumptions!$B$92:$B$115,0)),"Low") -> Low
B11: 19 | C11: TE | D11: Nagarkurnool | E11: =SUM(G11:I11) -> 0 | F11: =SUMIFS('CBG Plants'!N:N,'CBG Plants'!F:F,D11,'CBG Plants'!L:L,"Completed") +SUMIFS('CBG Plants'!N:N,'CBG Plants'!F:F,D11,'CBG Plants'!L:L,"Functional")+SUMIFS('CBG Plants'!N:N,'CBG Plants'!F:F,D11,'CBG Plants'!L:L,"Under Construction")+SUMIFS('CBG Plants'!N:N,'CBG Plants'!F:F,D11,'CBG Plants'!L:L,"Yet to start construction") -> 0 | G11: =COUNTIFS('CBG Plants'!F:F,D11,'CBG Plants'!L:L,"Completed") +COUNTIFS('CBG Plants'!F:F,D11,'CBG Plants'!L:L,"Functional") -> 0 | H11: =COUNTIFS('CBG Plants'!F:F,D11,'CBG Plants'!L:L,"Under Construction") -> 0 | I11: =COUNTIFS('CBG Plants'!F:F,D11,'CBG Plants'!L:L,"Yet to start construction") -> 0 | M11: =IFERROR(N11-(AD11*365/1000),"") -> 339.255 | N11: =SUM(O11:Q11) -> 339.255 | O11: 0 | P11: 190.68 | Q11: 148.575 | R11: =IFERROR(U11-F11,"") -> 0.22529145 | S11: =IFERROR(T11*Assumptions!$C$4,"") -> 7.5 | T11: 3 | U11: =IFERROR(S11*Assumptions!$C$5,"")+IFERROR(V11*Assumptions!$C$8*Assumptions!$C$5,"") -> 0.22529145 | V11: 29 | W11: =IFERROR(ROUND(T11*(1+Assumptions!$C$7)^5,0),"") -> 9 | X11: =IFERROR(ROUND(W11*Assumptions!$C$4*Assumptions!$C$6,4),"")+IFERROR(ROUND(Y11*Assumptions!$C$8*Assumptions!$C$6,4),"") - F11 -> 1.1265 | Y11: =IFERROR(ROUND(V11*(1+Assumptions!$C$7)^5,0),"") -> 89 | Z11: Operational Common Carrier | AA11: Kakinada-Hyderabad-Uran-Ahmedabad (East West Pipeline) | AB11: 108.4 | AC11: 85 | AD11: 0 | AE11: =IF(R11="","",IF(R11>=Control!$D$4,"Y","N")) -> N | AF11: =IF(S11="","",IF(M11>=Control!$D$5,"Y","N")) -> Y | AG11: =IF(T11="","",IF(AB11<=Control!$D$10,"Y","N")) -> Y | AI11: =IF(X11="","",IF(X11>=Control!$D$9,"Y","N")) -> N | AK11: =IFERROR(INDEX(Assumptions!$D$92:$D$115,MATCH(C11,Assumptions!$B$92:$B$115,0)),"Low") -> Low
B12: 10 | C12: TE | D12: Karimnagar | E12: =SUM(G12:I12) -> 0 | F12: =SUMIFS('CBG Plants'!N:N,'CBG Plants'!F:F,D12,'CBG Plants'!L:L,"Completed") +SUMIFS('CBG Plants'!N:N,'CBG Plants'!F:F,D12,'CBG Plants'!L:L,"Functional")+SUMIFS('CBG Plants'!N:N,'CBG Plants'!F:F,D12,'CBG Plants'!L:L,"Under Construction")+SUMIFS('CBG Plants'!N:N,'CBG Plants'!F:F,D12,'CBG Plants'!L:L,"Yet to start construction") -> 0 | G12: =COUNTIFS('CBG Plants'!F:F,D12,'CBG Plants'!L:L,"Completed") +COUNTIFS('CBG Plants'!F:F,D12,'CBG Plants'!L:L,"Functional") -> 0 | H12: =COUNTIFS('CBG Plants'!F:F,D12,'CBG Plants'!L:L,"Under Construction") -> 0 | I12: =COUNTIFS('CBG Plants'!F:F,D12,'CBG Plants'!L:L,"Yet to start construction") -> 0 | M12: =IFERROR(N12-(AD12*365/1000),"") -> 381.885 | N12: =SUM(O12:Q12) -> 381.885 | O12: 0 | P12: 326.76 | Q12: 55.125 | R12: =IFERROR(U12-F12,"") -> 0.15206025 | S12: =IFERROR(T12*Assumptions!$C$4,"") -> 5 | T12: 2 | U12: =IFERROR(S12*Assumptions!$C$5,"")+IFERROR(V12*Assumptions!$C$8*Assumptions!$C$5,"") -> 0.15206025 | V12: 205 | W12: =IFERROR(ROUND(T12*(1+Assumptions!$C$7)^5,0),"") -> 6 | X12: =IFERROR(ROUND(W12*Assumptions!$C$4*Assumptions!$C$6,4),"")+IFERROR(ROUND(Y12*Assumptions!$C$8*Assumptions!$C$6,4),"") - F12 -> 0.7605 | Y12: =IFERROR(ROUND(V12*(1+Assumptions!$C$7)^5,0),"") -> 626 | Z12: Operational Common Carrier | AA12: Kakinada-Hyderabad-Uran-Ahmedabad (East West Pipeline) | AB12: 118.1 | AC12: 85 | AD12: 0 | AE12: =IF(R12="","",IF(R12>=Control!$D$4,"Y","N")) -> N | AF12: =IF(S12="","",IF(M12>=Control!$D$5,"Y","N")) -> Y | AG12: =IF(T12="","",IF(AB12<=Control!$D$10,"Y","N")) -> Y | AI12: =IF(X12="","",IF(X12>=Control!$D$9,"Y","N")) -> N | AK12: =IFERROR(INDEX(Assumptions!$D$92:$D$115,MATCH(C12,Assumptions!$B$92:$B$115,0)),"Low") -> Low
B13: 24 | C13: TE | D13: Peddapalli | E13: =SUM(G13:I13) -> 0 | F13: =SUMIFS('CBG Plants'!N:N,'CBG Plants'!F:F,D13,'CBG Plants'!L:L,"Completed") +SUMIFS('CBG Plants'!N:N,'CBG Plants'!F:F,D13,'CBG Plants'!L:L,"Functional")+SUMIFS('CBG Plants'!N:N,'CBG Plants'!F:F,D13,'CBG Plants'!L:L,"Under Construction")+SUMIFS('CBG Plants'!N:N,'CBG Plants'!F:F,D13,'CBG Plants'!L:L,"Yet to start construction") -> 0 | G13: =COUNTIFS('CBG Plants'!F:F,D13,'CBG Plants'!L:L,"Completed") +COUNTIFS('CBG Plants'!F:F,D13,'CBG Plants'!L:L,"Functional") -> 0 | H13: =COUNTIFS('CBG Plants'!F:F,D13,'CBG Plants'!L:L,"Under Construction") -> 0 | I13: =COUNTIFS('CBG Plants'!F:F,D13,'CBG Plants'!L:L,"Yet to start construction") -> 0 | M13: =IFERROR(N13-(AD13*365/1000),"") -> 285.705 | N13: =SUM(O13:Q13) -> 285.705 | O13: 0 | P13: 251.58 | Q13: 34.125 | R13: =IFERROR(U13-F13,"") -> 0.15206025 | S13: =IFERROR(T13*Assumptions!$C$4,"") -> 5 | T13: 2 | U13: =IFERROR(S13*Assumptions!$C$5,"")+IFERROR(V13*Assumptions!$C$8*Assumptions!$C$5,"") -> 0.15206025 | V13: 205 | W13: =IFERROR(ROUND(T13*(1+Assumptions!$C$7)^5,0),"") -> 6 | X13: =IFERROR(ROUND(W13*Assumptions!$C$4*Assumptions!$C$6,4),"")+IFERROR(ROUND(Y13*Assumptions!$C$8*Assumptions!$C$6,4),"") - F13 -> 0.7605 | Y13: =IFERROR(ROUND(V13*(1+Assumptions!$C$7)^5,0),"") -> 626 | Z13: Operational Common Carrier | AA13: Kakinada-Hyderabad-Uran-Ahmedabad (East West Pipeline) | AB13: 147.1 | AC13: 85 | AD13: 0 | AE13: =IF(R13="","",IF(R13>=Control!$D$4,"Y","N")) -> N | AF13: =IF(S13="","",IF(M13>=Control!$D$5,"Y","N")) -> Y | AG13: =IF(T13="","",IF(AB13<=Control!$D$10,"Y","N")) -> Y | AI13: =IF(X13="","",IF(X13>=Control!$D$9,"Y","N")) -> N | AK13: =IFERROR(INDEX(Assumptions!$D$92:$D$115,MATCH(C13,Assumptions!$B$92:$B$115,0)),"Low") -> Low
B14: 25 | C14: TE | D14: Rajanna Sircilla | E14: =SUM(G14:I14) -> 0 | F14: =SUMIFS('CBG Plants'!N:N,'CBG Plants'!F:F,D14,'CBG Plants'!L:L,"Completed") +SUMIFS('CBG Plants'!N:N,'CBG Plants'!F:F,D14,'CBG Plants'!L:L,"Functional")+SUMIFS('CBG Plants'!N:N,'CBG Plants'!F:F,D14,'CBG Plants'!L:L,"Under Construction")+SUMIFS('CBG Plants'!N:N,'CBG Plants'!F:F,D14,'CBG Plants'!L:L,"Yet to start construction") -> 0 | G14: =COUNTIFS('CBG Plants'!F:F,D14,'CBG Plants'!L:L,"Completed") +COUNTIFS('CBG Plants'!F:F,D14,'CBG Plants'!L:L,"Functional") -> 0 | H14: =COUNTIFS('CBG Plants'!F:F,D14,'CBG Plants'!L:L,"Under Construction") -> 0 | I14: =COUNTIFS('CBG Plants'!F:F,D14,'CBG Plants'!L:L,"Yet to start construction") -> 0 | M14: =IFERROR(N14-(AD14*365/1000),"") -> 232.89 | N14: =SUM(O14:Q14) -> 232.89 | O14: 0 | P14: 227.64 | Q14: 5.25 | R14: =IFERROR(U14-F14,"") -> 0.15206025 | S14: =IFERROR(T14*Assumptions!$C$4,"") -> 5 | T14: 2 | U14: =IFERROR(S14*Assumptions!$C$5,"")+IFERROR(V14*Assumptions!$C$8*Assumptions!$C$5,"") -> 0.15206025 | V14: 205 | W14: =IFERROR(ROUND(T14*(1+Assumptions!$C$7)^5,0),"") -> 6 | X14: =IFERROR(ROUND(W14*Assumptions!$C$4*Assumptions!$C$6,4),"")+IFERROR(ROUND(Y14*Assumptions!$C$8*Assumptions!$C$6,4),"") - F14 -> 0.7605 | Y14: =IFERROR(ROUND(V14*(1+Assumptions!$C$7)^5,0),"") -> 626 | Z14: Operational Common Carrier | AA14: Kakinada-Hyderabad-Uran-Ahmedabad (East West Pipeline) | AB14: 117.5 | AC14: 85 | AD14: 0 | AE14: =IF(R14="","",IF(R14>=Control!$D$4,"Y","N")) -> N | AF14: =IF(S14="","",IF(M14>=Control!$D$5,"Y","N")) -> Y | AG14: =IF(T14="","",IF(AB14<=Control!$D$10,"Y","N")) -> Y | AI14: =IF(X14="","",IF(X14>=Control!$D$9,"Y","N")) -> N | AK14: =IFERROR(INDEX(Assumptions!$D$92:$D$115,MATCH(C14,Assumptions!$B$92:$B$115,0)),"Low") -> Low
B15: 7 | C15: TE | D15: Jayashankar Bhupalapally | E15: =SUM(G15:I15) -> 0 | F15: =SUMIFS('CBG Plants'!N:N,'CBG Plants'!F:F,D15,'CBG Plants'!L:L,"Completed") +SUMIFS('CBG Plants'!N:N,'CBG Plants'!F:F,D15,'CBG Plants'!L:L,"Functional")+SUMIFS('CBG Plants'!N:N,'CBG Plants'!F:F,D15,'CBG Plants'!L:L,"Under Construction")+SUMIFS('CBG Plants'!N:N,'CBG Plants'!F:F,D15,'CBG Plants'!L:L,"Yet to start construction") -> 0 | G15: =COUNTIFS('CBG Plants'!F:F,D15,'CBG Plants'!L:L,"Completed") +COUNTIFS('CBG Plants'!F:F,D15,'CBG Plants'!L:L,"Functional") -> 0 | H15: =COUNTIFS('CBG Plants'!F:F,D15,'CBG Plants'!L:L,"Under Construction") -> 0 | I15: =COUNTIFS('CBG Plants'!F:F,D15,'CBG Plants'!L:L,"Yet to start construction") -> 0 | M15: =IFERROR(N15-(AD15*365/1000),"") -> 138.81 | N15: =SUM(O15:Q15) -> 138.81 | O15: 0 | P15: 104.16 | Q15: 34.65 | R15: =IFERROR(U15-F15,"") -> 0 | S15: =IFERROR(T15*Assumptions!$C$4,"") -> 0 | T15: 0 | U15: =IFERROR(S15*Assumptions!$C$5,"")+IFERROR(V15*Assumptions!$C$8*Assumptions!$C$5,"") -> 0 | V15: 0 | W15: =IFERROR(ROUND(T15*(1+Assumptions!$C$7)^5,0),"") -> 0 | X15: =IFERROR(ROUND(W15*Assumptions!$C$4*Assumptions!$C$6,4),"")+IFERROR(ROUND(Y15*Assumptions!$C$8*Assumptions!$C$6,4),"") - F15 -> 0 | Y15: =IFERROR(ROUND(V15*(1+Assumptions!$C$7)^5,0),"") -> 0 | Z15: Operational Common Carrier | AA15: Kakinada-Hyderabad-Uran-Ahmedabad (East West Pipeline) | AB15: 139.7 | AC15: 85 | AD15: 0 | AE15: =IF(R15="","",IF(R15>=Control!$D$4,"Y","N")) -> N | AF15: =IF(S15="","",IF(M15>=Control!$D$5,"Y","N")) -> Y | AG15: =IF(T15="","",IF(AB15<=Control!$D$10,"Y","N")) -> Y | AI15: =IF(X15="","",IF(X15>=Control!$D$9,"Y","N")) -> N | AK15: =IFERROR(INDEX(Assumptions!$D$92:$D$115,MATCH(C15,Assumptions!$B$92:$B$115,0)),"Low") -> Low
B16: 27 | C16: TE | D16: Sangareddy | E16: =SUM(G16:I16) -> 2 | F16: =SUMIFS('CBG Plants'!N:N,'CBG Plants'!F:F,D16,'CBG Plants'!L:L,"Completed") +SUMIFS('CBG Plants'!N:N,'CBG Plants'!F:F,D16,'CBG Plants'!L:L,"Functional")+SUMIFS('CBG Plants'!N:N,'CBG Plants'!F:F,D16,'CBG Plants'!L:L,"Under Construction")+SUMIFS('CBG Plants'!N:N,'CBG Plants'!F:F,D16,'CBG Plants'!L:L,"Yet to start construction") -> 2.58 | G16: =COUNTIFS('CBG Plants'!F:F,D16,'CBG Plants'!L:L,"Completed") +COUNTIFS('CBG Plants'!F:F,D16,'CBG Plants'!L:L,"Functional") -> 0 | H16: =COUNTIFS('CBG Plants'!F:F,D16,'CBG Plants'!L:L,"Under Construction") -> 1 | I16: =COUNTIFS('CBG Plants'!F:F,D16,'CBG Plants'!L:L,"Yet to start construction") -> 1 | J16: BLUELEO-01 | K16: Blue leo by bia green pvt ltd | M16: =IFERROR(N16-(AD16*365/1000),"") -> 173.46 | N16: =SUM(O16:Q16) -> 173.46 | O16: 0 | P16: 162.96 | Q16: 10.5 | R16: =IFERROR(U16-F16,"") -> -2.0450706 | S16: =IFERROR(T16*Assumptions!$C$4,"") -> 17.5 | T16: 7 | U16: =IFERROR(S16*Assumptions!$C$5,"")+IFERROR(V16*Assumptions!$C$8*Assumptions!$C$5,"") -> 0.5349294 | V16: 988 | W16: =IFERROR(ROUND(T16*(1+Assumptions!$C$7)^5,0),"") -> 21 | X16: =IFERROR(ROUND(W16*Assumptions!$C$4*Assumptions!$C$6,4),"")+IFERROR(ROUND(Y16*Assumptions!$C$8*Assumptions!$C$6,4),"") - F16 -> 0.0955 | Y16: =IFERROR(ROUND(V16*(1+Assumptions!$C$7)^5,0),"") -> 3015 | Z16: Operational Common Carrier | AA16: Kakinada-Hyderabad-Uran-Ahmedabad (East West Pipeline) | AB16: 25 | AC16: 85 | AD16: 0 | AE16: =IF(R16="","",IF(R16>=Control!$D$4,"Y","N")) -> N | AF16: =IF(S16="","",IF(M16>=Control!$D$5,"Y","N")) -> Y | AG16: =IF(T16="","",IF(AB16<=Control!$D$10,"Y","N")) -> Y | AI16: =IF(X16="","",IF(X16>=Control!$D$9,"Y","N")) -> N | AK16: =IFERROR(INDEX(Assumptions!$D$92:$D$115,MATCH(C16,Assumptions!$B$92:$B$115,0)),"Low") -> Low
B17: 31 | C17: TE | D17: Wanaparthy | E17: =SUM(G17:I17) -> 1 | F17: =SUMIFS('CBG Plants'!N:N,'CBG Plants'!F:F,D17,'CBG Plants'!L:L,"Completed") +SUMIFS('CBG Plants'!N:N,'CBG Plants'!F:F,D17,'CBG Plants'!L:L,"Functional")+SUMIFS('CBG Plants'!N:N,'CBG Plants'!F:F,D17,'CBG Plants'!L:L,"Under Construction")+SUMIFS('CBG Plants'!N:N,'CBG Plants'!F:F,D17,'CBG Plants'!L:L,"Yet to start construction") -> 3.8 | G17: =COUNTIFS('CBG Plants'!F:F,D17,'CBG Plants'!L:L,"Completed") +COUNTIFS('CBG Plants'!F:F,D17,'CBG Plants'!L:L,"Functional") -> 0 | H17: =COUNTIFS('CBG Plants'!F:F,D17,'CBG Plants'!L:L,"Under Construction") -> 1 | I17: =COUNTIFS('CBG Plants'!F:F,D17,'CBG Plants'!L:L,"Yet to start construction") -> 0 | J17: Bio CNG | M17: =IFERROR(N17-(AD17*365/1000),"") -> 218.4 | N17: =SUM(O17:Q17) -> 218.4 | O17: 0 | P17: 205.8 | Q17: 12.6 | R17: =IFERROR(U17-F17,"") -> -3.5747085 | S17: =IFERROR(T17*Assumptions!$C$4,"") -> 7.5 | T17: 3 | U17: =IFERROR(S17*Assumptions!$C$5,"")+IFERROR(V17*Assumptions!$C$8*Assumptions!$C$5,"") -> 0.22529145 | V17: 29 | W17: =IFERROR(ROUND(T17*(1+Assumptions!$C$7)^5,0),"") -> 9 | X17: =IFERROR(ROUND(W17*Assumptions!$C$4*Assumptions!$C$6,4),"")+IFERROR(ROUND(Y17*Assumptions!$C$8*Assumptions!$C$6,4),"") - F17 -> -2.6735 | Y17: =IFERROR(ROUND(V17*(1+Assumptions!$C$7)^5,0),"") -> 89 | Z17: Operational Common Carrier | AA17: Kakinada-Hyderabad-Uran-Ahmedabad (East West Pipeline) | AB17: 129.2 | AC17: 85 | AD17: 0 | AE17: =IF(R17="","",IF(R17>=Control!$D$4,"Y","N")) -> N | AF17: =IF(S17="","",IF(M17>=Control!$D$5,"Y","N")) -> Y | AG17: =IF(T17="","",IF(AB17<=Control!$D$10,"Y","N")) -> Y | AI17: =IF(X17="","",IF(X17>=Control!$D$9,"Y","N")) -> N | AK17: =IFERROR(INDEX(Assumptions!$D$92:$D$115,MATCH(C17,Assumptions!$B$92:$B$115,0)),"Low") -> Low
B18: 30 | C18: TE | D18: Vikarabad | E18: =SUM(G18:I18) -> 2 | F18: =SUMIFS('CBG Plants'!N:N,'CBG Plants'!F:F,D18,'CBG Plants'!L:L,"Completed") +SUMIFS('CBG Plants'!N:N,'CBG Plants'!F:F,D18,'CBG Plants'!L:L,"Functional")+SUMIFS('CBG Plants'!N:N,'CBG Plants'!F:F,D18,'CBG Plants'!L:L,"Under Construction")+SUMIFS('CBG Plants'!N:N,'CBG Plants'!F:F,D18,'CBG Plants'!L:L,"Yet to start construction") -> 5.5 | G18: =COUNTIFS('CBG Plants'!F:F,D18,'CBG Plants'!L:L,"Completed") +COUNTIFS('CBG Plants'!F:F,D18,'CBG Plants'!L:L,"Functional") -> 0 | H18: =COUNTIFS('CBG Plants'!F:F,D18,'CBG Plants'!L:L,"Under Construction") -> 0 | I18: =COUNTIFS('CBG Plants'!F:F,D18,'CBG Plants'!L:L,"Yet to start construction") -> 2 | J18: CBG plant | K18: GODESI AGRO RENEWABLE ENERGY | M18: =IFERROR(N18-(AD18*365/1000),"") -> 150.78 | N18: =SUM(O18:Q18) -> 150.78 | O18: 0 | P18: 117.18 | Q18: 33.6 | R18: =IFERROR(U18-F18,"") -> -4.7278398 | S18: =IFERROR(T18*Assumptions!$C$4,"") -> 25 | T18: 10 | U18: =IFERROR(S18*Assumptions!$C$5,"")+IFERROR(V18*Assumptions!$C$8*Assumptions!$C$5,"") -> 0.77216025 | V18: 2205 | W18: =IFERROR(ROUND(T18*(1+Assumptions!$C$7)^5,0),"") -> 31 | X18: =IFERROR(ROUND(W18*Assumptions!$C$4*Assumptions!$C$6,4),"")+IFERROR(ROUND(Y18*Assumptions!$C$8*Assumptions!$C$6,4),"") - F18 -> -1.5123 | Y18: =IFERROR(ROUND(V18*(1+Assumptions!$C$7)^5,0),"") -> 6729 | Z18: Operational Common Carrier | AA18: Kakinada-Hyderabad-Uran-Ahmedabad (East West Pipeline) | AB18: 35.9 | AC18: 85 | AD18: 0 | AE18: =IF(R18="","",IF(R18>=Control!$D$4,"Y","N")) -> N | AF18: =IF(S18="","",IF(M18>=Control!$D$5,"Y","N")) -> Y | AG18: =IF(T18="","",IF(AB18<=Control!$D$10,"Y","N")) -> Y | AI18: =IF(X18="","",IF(X18>=Control!$D$9,"Y","N")) -> N | AK18: =IFERROR(INDEX(Assumptions!$D$92:$D$115,MATCH(C18,Assumptions!$B$92:$B$115,0)),"Low") -> Low
B19: 14 | C19: TE | D19: Mahbubnagar | E19: =SUM(G19:I19) -> 2 | F19: =SUMIFS('CBG Plants'!N:N,'CBG Plants'!F:F,D19,'CBG Plants'!L:L,"Completed") +SUMIFS('CBG Plants'!N:N,'CBG Plants'!F:F,D19,'CBG Plants'!L:L,"Functional")+SUMIFS('CBG Plants'!N:N,'CBG Plants'!F:F,D19,'CBG Plants'!L:L,"Under Construction")+SUMIFS('CBG Plants'!N:N,'CBG Plants'!F:F,D19,'CBG Plants'!L:L,"Yet to start construction") -> 7 | G19: =COUNTIFS('CBG Plants'!F:F,D19,'CBG Plants'!L:L,"Completed") +COUNTIFS('CBG Plants'!F:F,D19,'CBG Plants'!L:L,"Functional") -> 1 | H19: =COUNTIFS('CBG Plants'!F:F,D19,'CBG Plants'!L:L,"Under Construction") -> 0 | I19: =COUNTIFS('CBG Plants'!F:F,D19,'CBG Plants'!L:L,"Yet to start construction") -> 1 | J19: USHODAYAM BIOENERGY PRIVATE LIMITED | K19: Solika Energy - Udithyal | M19: =IFERROR(N19-(AD19*365/1000),"") -> 214.77 | N19: =SUM(O19:Q19) -> 236.67 | O19: 0 | P19: 208.32 | Q19: 28.35 | R19: =IFERROR(U19-F19,"") -> -6.7747085 | S19: =IFERROR(T19*Assumptions!$C$4,"") -> 7.5 | T19: 3 | U19: =IFERROR(S19*Assumptions!$C$5,"")+IFERROR(V19*Assumptions!$C$8*Assumptions!$C$5,"") -> 0.22529145 | V19: 29 | W19: =IFERROR(ROUND(T19*(1+Assumptions!$C$7)^5,0),"") -> 9 | X19: =IFERROR(ROUND(W19*Assumptions!$C$4*Assumptions!$C$6,4),"")+IFERROR(ROUND(Y19*Assumptions!$C$8*Assumptions!$C$6,4),"") - F19 -> -5.8735 | Y19: =IFERROR(ROUND(V19*(1+Assumptions!$C$7)^5,0),"") -> 89 | Z19: Operational Common Carrier | AA19: Kakinada-Hyderabad-Uran-Ahmedabad (East West Pipeline) | AB19: 81.7 | AC19: 85 | AD19: 60 | AE19: =IF(R19="","",IF(R19>=Control!$D$4,"Y","N")) -> N | AF19: =IF(S19="","",IF(M19>=Control!$D$5,"Y","N")) -> Y | AG19: =IF(T19="","",IF(AB19<=Control!$D$10,"Y","N")) -> Y | AI19: =IF(X19="","",IF(X19>=Control!$D$9,"Y","N")) -> N | AK19: =IFERROR(INDEX(Assumptions!$D$92:$D$115,MATCH(C19,Assumptions!$B$92:$B$115,0)),"Low") -> Low
B20: 5 | C20: TE | D20: Jagtial | E20: =SUM(G20:I20) -> 2 | F20: =SUMIFS('CBG Plants'!N:N,'CBG Plants'!F:F,D20,'CBG Plants'!L:L,"Completed") +SUMIFS('CBG Plants'!N:N,'CBG Plants'!F:F,D20,'CBG Plants'!L:L,"Functional")+SUMIFS('CBG Plants'!N:N,'CBG Plants'!F:F,D20,'CBG Plants'!L:L,"Under Construction")+SUMIFS('CBG Plants'!N:N,'CBG Plants'!F:F,D20,'CBG Plants'!L:L,"Yet to start construction") -> 7 | G20: =COUNTIFS('CBG Plants'!F:F,D20,'CBG Plants'!L:L,"Completed") +COUNTIFS('CBG Plants'!F:F,D20,'CBG Plants'!L:L,"Functional") -> 0 | H20: =COUNTIFS('CBG Plants'!F:F,D20,'CBG Plants'!L:L,"Under Construction") -> 0 | I20: =COUNTIFS('CBG Plants'!F:F,D20,'CBG Plants'!L:L,"Yet to start construction") -> 2 | J20: EcoMax Energy Karimnagar | K20: Alyra Bio fuels and Fertilizers | M20: =IFERROR(N20-(AD20*365/1000),"") -> 0 | N20: =SUM(O20:Q20) -> 0 | R20: =IFERROR(U20-F20,"") -> -6.8479398 | S20: =IFERROR(T20*Assumptions!$C$4,"") -> 5 | T20: 2 | U20: =IFERROR(S20*Assumptions!$C$5,"")+IFERROR(V20*Assumptions!$C$8*Assumptions!$C$5,"") -> 0.15206025 | V20: 205 | W20: =IFERROR(ROUND(T20*(1+Assumptions!$C$7)^5,0),"") -> 6 | X20: =IFERROR(ROUND(W20*Assumptions!$C$4*Assumptions!$C$6,4),"")+IFERROR(ROUND(Y20*Assumptions!$C$8*Assumptions!$C$6,4),"") - F20 -> -6.2395 | Y20: =IFERROR(ROUND(V20*(1+Assumptions!$C$7)^5,0),"") -> 626 | Z20: Operational Common Carrier | AA20: Kakinada-Hyderabad-Uran-Ahmedabad (East West Pipeline) | AB20: 163.8 | AC20: 85 | AD20: 0 | AE20: =IF(R20="","",IF(R20>=Control!$D$4,"Y","N")) -> N | AF20: =IF(S20="","",IF(M20>=Control!$D$5,"Y","N")) -> N | AG20: =IF(T20="","",IF(AB20<=Control!$D$10,"Y","N")) -> Y | AI20: =IF(X20="","",IF(X20>=Control!$D$9,"Y","N")) -> N | AK20: =IFERROR(INDEX(Assumptions!$D$92:$D$115,MATCH(C20,Assumptions!$B$92:$B$115,0)),"Low") -> Low
B21: 11 | C21: TE | D21: Khammam | E21: =SUM(G21:I21) -> 2 | F21: =SUMIFS('CBG Plants'!N:N,'CBG Plants'!F:F,D21,'CBG Plants'!L:L,"Completed") +SUMIFS('CBG Plants'!N:N,'CBG Plants'!F:F,D21,'CBG Plants'!L:L,"Functional")+SUMIFS('CBG Plants'!N:N,'CBG Plants'!F:F,D21,'CBG Plants'!L:L,"Under Construction")+SUMIFS('CBG Plants'!N:N,'CBG Plants'!F:F,D21,'CBG Plants'!L:L,"Yet to start construction") -> 7.5 | G21: =COUNTIFS('CBG Plants'!F:F,D21,'CBG Plants'!L:L,"Completed") +COUNTIFS('CBG Plants'!F:F,D21,'CBG Plants'!L:L,"Functional") -> 0 | H21: =COUNTIFS('CBG Plants'!F:F,D21,'CBG Plants'!L:L,"Under Construction") -> 1 | I21: =COUNTIFS('CBG Plants'!F:F,D21,'CBG Plants'!L:L,"Yet to start construction") -> 1 | J21: AGRIVERT BIOFUELS PRIVATE LIMITED | K21: VAYU SHAKTHI | M21: =IFERROR(N21-(AD21*365/1000),"") -> 482.16 | N21: =SUM(O21:Q21) -> 482.16 | O21: 0 | P21: 295.26 | Q21: 186.9 | R21: =IFERROR(U21-F21,"") -> -6.9638646 | S21: =IFERROR(T21*Assumptions!$C$4,"") -> 17.5 | T21: 7 | U21: =IFERROR(S21*Assumptions!$C$5,"")+IFERROR(V21*Assumptions!$C$8*Assumptions!$C$5,"") -> 0.5361354 | V21: 1108 | W21: =IFERROR(ROUND(T21*(1+Assumptions!$C$7)^5,0),"") -> 21 | X21: =IFERROR(ROUND(W21*Assumptions!$C$4*Assumptions!$C$6,4),"")+IFERROR(ROUND(Y21*Assumptions!$C$8*Assumptions!$C$6,4),"") - F21 -> -4.8184 | Y21: =IFERROR(ROUND(V21*(1+Assumptions!$C$7)^5,0),"") -> 3381 | Z21: Operational Common Carrier | AA21: Kakinada-Hyderabad-Uran-Ahmedabad (East West Pipeline) | AB21: 0.6 | AC21: 85 | AD21: 0 | AE21: =IF(R21="","",IF(R21>=Control!$D$4,"Y","N")) -> N | AF21: =IF(S21="","",IF(M21>=Control!$D$5,"Y","N")) -> Y | AG21: =IF(T21="","",IF(AB21<=Control!$D$10,"Y","N")) -> Y | AI21: =IF(X21="","",IF(X21>=Control!$D$9,"Y","N")) -> N | AK21: =IFERROR(INDEX(Assumptions!$D$92:$D$115,MATCH(C21,Assumptions!$B$92:$B$115,0)),"Low") -> Low
B22: 18 | C22: TE | D22: Mulugu | E22: =SUM(G22:I22) -> 2 | F22: =SUMIFS('CBG Plants'!N:N,'CBG Plants'!F:F,D22,'CBG Plants'!L:L,"Completed") +SUMIFS('CBG Plants'!N:N,'CBG Plants'!F:F,D22,'CBG Plants'!L:L,"Functional")+SUMIFS('CBG Plants'!N:N,'CBG Plants'!F:F,D22,'CBG Plants'!L:L,"Under Construction")+SUMIFS('CBG Plants'!N:N,'CBG Plants'!F:F,D22,'CBG Plants'!L:L,"Yet to start construction") -> 9 | G22: =COUNTIFS('CBG Plants'!F:F,D22,'CBG Plants'!L:L,"Completed") +COUNTIFS('CBG Plants'!F:F,D22,'CBG Plants'!L:L,"Functional") -> 0 | H22: =COUNTIFS('CBG Plants'!F:F,D22,'CBG Plants'!L:L,"Under Construction") -> 0 | I22: =COUNTIFS('CBG Plants'!F:F,D22,'CBG Plants'!L:L,"Yet to start construction") -> 2 | J22: Mulugu Bio Energy | K22: KASHYAPA ECOFUELS | M22: =IFERROR(N22-(AD22*365/1000),"") -> 93.03 | N22: =SUM(O22:Q22) -> 93.03 | O22: 0 | P22: 73.08 | Q22: 19.95 | R22: =IFERROR(U22-F22,"") -> -9 | S22: =IFERROR(T22*Assumptions!$C$4,"") -> 0 | T22: 0 | U22: =IFERROR(S22*Assumptions!$C$5,"")+IFERROR(V22*Assumptions!$C$8*Assumptions!$C$5,"") -> 0 | V22: 0 | W22: =IFERROR(ROUND(T22*(1+Assumptions!$C$7)^5,0),"") -> 0 | X22: =IFERROR(ROUND(W22*Assumptions!$C$4*Assumptions!$C$6,4),"")+IFERROR(ROUND(Y22*Assumptions!$C$8*Assumptions!$C$6,4),"") - F22 -> -9 | Y22: =IFERROR(ROUND(V22*(1+Assumptions!$C$7)^5,0),"") -> 0 | Z22: Operational Common Carrier | AA22: Kakinada-Hyderabad-Uran-Ahmedabad (East West Pipeline) | AB22: 121.1 | AC22: 85 | AD22: 0 | AE22: =IF(R22="","",IF(R22>=Control!$D$4,"Y","N")) -> N | AF22: =IF(S22="","",IF(M22>=Control!$D$5,"Y","N")) -> Y | AG22: =IF(T22="","",IF(AB22<=Control!$D$10,"Y","N")) -> Y | AI22: =IF(X22="","",IF(X22>=Control!$D$9,"Y","N")) -> N | AK22: =IFERROR(INDEX(Assumptions!$D$92:$D$115,MATCH(C22,Assumptions!$B$92:$B$115,0)),"Low") -> Low
B23: 28 | C23: TE | D23: Siddipet | E23: =SUM(G23:I23) -> 2 | F23: =SUMIFS('CBG Plants'!N:N,'CBG Plants'!F:F,D23,'CBG Plants'!L:L,"Completed") +SUMIFS('CBG Plants'!N:N,'CBG Plants'!F:F,D23,'CBG Plants'!L:L,"Functional")+SUMIFS('CBG Plants'!N:N,'CBG Plants'!F:F,D23,'CBG Plants'!L:L,"Under Construction")+SUMIFS('CBG Plants'!N:N,'CBG Plants'!F:F,D23,'CBG Plants'!L:L,"Yet to start construction") -> 11 | G23: =COUNTIFS('CBG Plants'!F:F,D23,'CBG Plants'!L:L,"Completed") +COUNTIFS('CBG Plants'!F:F,D23,'CBG Plants'!L:L,"Functional") -> 1 | H23: =COUNTIFS('CBG Plants'!F:F,D23,'CBG Plants'!L:L,"Under Construction") -> 0 | I23: =COUNTIFS('CBG Plants'!F:F,D23,'CBG Plants'!L:L,"Yet to start construction") -> 1 | J23: Juno Joule Bio Fuels Telangana 10 TPD Plant | K23: Carbon Masters Biogas Plant | M23: =IFERROR(N23-(AD23*365/1000),"") -> 509.43 | N23: =SUM(O23:Q23) -> 520.38 | O23: 0 | P23: 453.18 | Q23: 67.2 | R23: =IFERROR(U23-F23,"") -> -10.465071 | S23: =IFERROR(T23*Assumptions!$C$4,"") -> 17.5 | T23: 7 | U23: =IFERROR(S23*Assumptions!$C$5,"")+IFERROR(V23*Assumptions!$C$8*Assumptions!$C$5,"") -> 0.5349294 | V23: 988 | W23: =IFERROR(ROUND(T23*(1+Assumptions!$C$7)^5,0),"") -> 21 | X23: =IFERROR(ROUND(W23*Assumptions!$C$4*Assumptions!$C$6,4),"")+IFERROR(ROUND(Y23*Assumptions!$C$8*Assumptions!$C$6,4),"") - F23 -> -8.3245 | Y23: =IFERROR(ROUND(V23*(1+Assumptions!$C$7)^5,0),"") -> 3015 | Z23: Operational Common Carrier | AA23: Kakinada-Hyderabad-Uran-Ahmedabad (East West Pipeline) | AB23: 73.1 | AC23: 85 | AD23: 30 | AE23: =IF(R23="","",IF(R23>=Control!$D$4,"Y","N")) -> N | AF23: =IF(S23="","",IF(M23>=Control!$D$5,"Y","N")) -> Y | AG23: =IF(T23="","",IF(AB23<=Control!$D$10,"Y","N")) -> Y | AI23: =IF(X23="","",IF(X23>=Control!$D$9,"Y","N")) -> N | AK23: =IFERROR(INDEX(Assumptions!$D$92:$D$115,MATCH(C23,Assumptions!$B$92:$B$115,0)),"Low") -> Low
B24: 15 | C24: TE | D24: Mancherial | E24: =SUM(G24:I24) -> 1 | F24: =SUMIFS('CBG Plants'!N:N,'CBG Plants'!F:F,D24,'CBG Plants'!L:L,"Completed") +SUMIFS('CBG Plants'!N:N,'CBG Plants'!F:F,D24,'CBG Plants'!L:L,"Functional")+SUMIFS('CBG Plants'!N:N,'CBG Plants'!F:F,D24,'CBG Plants'!L:L,"Under Construction")+SUMIFS('CBG Plants'!N:N,'CBG Plants'!F:F,D24,'CBG Plants'!L:L,"Yet to start construction") -> 12 | G24: =COUNTIFS('CBG Plants'!F:F,D24,'CBG Plants'!L:L,"Completed") +COUNTIFS('CBG Plants'!F:F,D24,'CBG Plants'!L:L,"Functional") -> 0 | H24: =COUNTIFS('CBG Plants'!F:F,D24,'CBG Plants'!L:L,"Under Construction") -> 0 | I24: =COUNTIFS('CBG Plants'!F:F,D24,'CBG Plants'!L:L,"Yet to start construction") -> 1 | J24: Prathmay Projects Pvt Ltd Compressed bio gas | M24: =IFERROR(N24-(AD24*365/1000),"") -> 146.475 | N24: =SUM(O24:Q24) -> 146.475 | O24: 0 | P24: 142.8 | Q24: 3.675 | R24: =IFERROR(U24-F24,"") -> -11.625 | S24: =IFERROR(T24*Assumptions!$C$4,"") -> 12.5 | T24: 5 | U24: =IFERROR(S24*Assumptions!$C$5,"")+IFERROR(V24*Assumptions!$C$8*Assumptions!$C$5,"") -> 0.375 | V24: 0 | W24: =IFERROR(ROUND(T24*(1+Assumptions!$C$7)^5,0),"") -> 15 | X24: =IFERROR(ROUND(W24*Assumptions!$C$4*Assumptions!$C$6,4),"")+IFERROR(ROUND(Y24*Assumptions!$C$8*Assumptions!$C$6,4),"") - F24 -> -10.125 | Y24: =IFERROR(ROUND(V24*(1+Assumptions!$C$7)^5,0),"") -> 0 | Z24: Operational Common Carrier | AA24: Kakinada-Hyderabad-Uran-Ahmedabad (East West Pipeline) | AB24: 189 | AC24: 85 | AD24: 0 | AE24: =IF(R24="","",IF(R24>=Control!$D$4,"Y","N")) -> N | AF24: =IF(S24="","",IF(M24>=Control!$D$5,"Y","N")) -> Y | AG24: =IF(T24="","",IF(AB24<=Control!$D$10,"Y","N")) -> Y | AI24: =IF(X24="","",IF(X24>=Control!$D$9,"Y","N")) -> N | AK24: =IFERROR(INDEX(Assumptions!$D$92:$D$115,MATCH(C24,Assumptions!$B$92:$B$115,0)),"Low") -> Low
B25: 8 | C25: TE | D25: Jogulamba Gadwal | E25: =SUM(G25:I25) -> 1 | F25: =SUMIFS('CBG Plants'!N:N,'CBG Plants'!F:F,D25,'CBG Plants'!L:L,"Completed") +SUMIFS('CBG Plants'!N:N,'CBG Plants'!F:F,D25,'CBG Plants'!L:L,"Functional")+SUMIFS('CBG Plants'!N:N,'CBG Plants'!F:F,D25,'CBG Plants'!L:L,"Under Construction")+SUMIFS('CBG Plants'!N:N,'CBG Plants'!F:F,D25,'CBG Plants'!L:L,"Yet to start construction") -> 12 | G25: =COUNTIFS('CBG Plants'!F:F,D25,'CBG Plants'!L:L,"Completed") +COUNTIFS('CBG Plants'!F:F,D25,'CBG Plants'!L:L,"Functional") -> 0 | H25: =COUNTIFS('CBG Plants'!F:F,D25,'CBG Plants'!L:L,"Under Construction") -> 0 | I25: =COUNTIFS('CBG Plants'!F:F,D25,'CBG Plants'!L:L,"Yet to start construction") -> 1 | J25: Sri Hanuman Green Energies Unit-1 | M25: =IFERROR(N25-(AD25*365/1000),"") -> 141.96 | N25: =SUM(O25:Q25) -> 141.96 | O25: 0 | P25: 87.36 | Q25: 54.6 | R25: =IFERROR(U25-F25,"") -> -11.774709 | S25: =IFERROR(T25*Assumptions!$C$4,"") -> 7.5 | T25: 3 | U25: =IFERROR(S25*Assumptions!$C$5,"")+IFERROR(V25*Assumptions!$C$8*Assumptions!$C$5,"") -> 0.22529145 | V25: 29 | W25: =IFERROR(ROUND(T25*(1+Assumptions!$C$7)^5,0),"") -> 9 | X25: =IFERROR(ROUND(W25*Assumptions!$C$4*Assumptions!$C$6,4),"")+IFERROR(ROUND(Y25*Assumptions!$C$8*Assumptions!$C$6,4),"") - F25 -> -10.8735 | Y25: =IFERROR(ROUND(V25*(1+Assumptions!$C$7)^5,0),"") -> 89 | Z25: Operational Common Carrier | AA25: Kakinada-Hyderabad-Uran-Ahmedabad (East West Pipeline) | AB25: 160.2 | AC25: 85 | AD25: 0 | AE25: =IF(R25="","",IF(R25>=Control!$D$4,"Y","N")) -> N | AF25: =IF(S25="","",IF(M25>=Control!$D$5,"Y","N")) -> Y | AG25: =IF(T25="","",IF(AB25<=Control!$D$10,"Y","N")) -> Y | AI25: =IF(X25="","",IF(X25>=Control!$D$9,"Y","N")) -> N | AK25: =IFERROR(INDEX(Assumptions!$D$92:$D$115,MATCH(C25,Assumptions!$B$92:$B$115,0)),"Low") -> Low
B26: 23 | C26: TE | D26: Nizamabad | E26: =SUM(G26:I26) -> 1 | F26: =SUMIFS('CBG Plants'!N:N,'CBG Plants'!F:F,D26,'CBG Plants'!L:L,"Completed") +SUMIFS('CBG Plants'!N:N,'CBG Plants'!F:F,D26,'CBG Plants'!L:L,"Functional")+SUMIFS('CBG Plants'!N:N,'CBG Plants'!F:F,D26,'CBG Plants'!L:L,"Under Construction")+SUMIFS('CBG Plants'!N:N,'CBG Plants'!F:F,D26,'CBG Plants'!L:L,"Yet to start construction") -> 20 | G26: =COUNTIFS('CBG Plants'!F:F,D26,'CBG Plants'!L:L,"Completed") +COUNTIFS('CBG Plants'!F:F,D26,'CBG Plants'!L:L,"Functional") -> 0 | H26: =COUNTIFS('CBG Plants'!F:F,D26,'CBG Plants'!L:L,"Under Construction") -> 0 | I26: =COUNTIFS('CBG Plants'!F:F,D26,'CBG Plants'!L:L,"Yet to start construction") -> 1 | J26: Compressed bio gas plant | M26: =IFERROR(N26-(AD26*365/1000),"") -> 697.095 | N26: =SUM(O26:Q26) -> 697.095 | O26: 0 | P26: 592.62 | Q26: 104.475 | R26: =IFERROR(U26-F26,"") -> -19.625 | S26: =IFERROR(T26*Assumptions!$C$4,"") -> 12.5 | T26: 5 | U26: =IFERROR(S26*Assumptions!$C$5,"")+IFERROR(V26*Assumptions!$C$8*Assumptions!$C$5,"") -> 0.375 | V26: 0 | W26: =IFERROR(ROUND(T26*(1+Assumptions!$C$7)^5,0),"") -> 15 | X26: =IFERROR(ROUND(W26*Assumptions!$C$4*Assumptions!$C$6,4),"")+IFERROR(ROUND(Y26*Assumptions!$C$8*Assumptions!$C$6,4),"") - F26 -> -18.125 | Y26: =IFERROR(ROUND(V26*(1+Assumptions!$C$7)^5,0),"") -> 0 | Z26: Operational Common Carrier | AA26: Kakinada-Hyderabad-Uran-Ahmedabad (East West Pipeline) | AB26: 132.3 | AC26: 85 | AD26: 0 | AE26: =IF(R26="","",IF(R26>=Control!$D$4,"Y","N")) -> N | AF26: =IF(S26="","",IF(M26>=Control!$D$5,"Y","N")) -> Y | AG26: =IF(T26="","",IF(AB26<=Control!$D$10,"Y","N")) -> Y | AI26: =IF(X26="","",IF(X26>=Control!$D$9,"Y","N")) -> N | AK26: =IFERROR(INDEX(Assumptions!$D$92:$D$115,MATCH(C26,Assumptions!$B$92:$B$115,0)),"Low") -> Low
B27: 21 | C27: TE | D27: Narayanpet | E27: =SUM(G27:I27) -> 1 | F27: =SUMIFS('CBG Plants'!N:N,'CBG Plants'!F:F,D27,'CBG Plants'!L:L,"Completed") +SUMIFS('CBG Plants'!N:N,'CBG Plants'!F:F,D27,'CBG Plants'!L:L,"Functional")+SUMIFS('CBG Plants'!N:N,'CBG Plants'!F:F,D27,'CBG Plants'!L:L,"Under Construction")+SUMIFS('CBG Plants'!N:N,'CBG Plants'!F:F,D27,'CBG Plants'!L:L,"Yet to start construction") -> 20 | G27: =COUNTIFS('CBG Plants'!F:F,D27,'CBG Plants'!L:L,"Completed") +COUNTIFS('CBG Plants'!F:F,D27,'CBG Plants'!L:L,"Functional") -> 0 | H27: =COUNTIFS('CBG Plants'!F:F,D27,'CBG Plants'!L:L,"Under Construction") -> 0 | I27: =COUNTIFS('CBG Plants'!F:F,D27,'CBG Plants'!L:L,"Yet to start construction") -> 1 | J27: Devsristi Energy Private Limited | M27: =IFERROR(N27-(AD27*365/1000),"") -> 189.945 | N27: =SUM(O27:Q27) -> 189.945 | O27: 0 | P27: 189.42 | Q27: 0.525 | R27: =IFERROR(U27-F27,"") -> -19.774709 | S27: =IFERROR(T27*Assumptions!$C$4,"") -> 7.5 | T27: 3 | U27: =IFERROR(S27*Assumptions!$C$5,"")+IFERROR(V27*Assumptions!$C$8*Assumptions!$C$5,"") -> 0.22529145 | V27: 29 | W27: =IFERROR(ROUND(T27*(1+Assumptions!$C$7)^5,0),"") -> 9 | X27: =IFERROR(ROUND(W27*Assumptions!$C$4*Assumptions!$C$6,4),"")+IFERROR(ROUND(Y27*Assumptions!$C$8*Assumptions!$C$6,4),"") - F27 -> -18.8735 | Y27: =IFERROR(ROUND(V27*(1+Assumptions!$C$7)^5,0),"") -> 89 | Z27: Operational Common Carrier | AA27: Kakinada-Hyderabad-Uran-Ahmedabad (East West Pipeline) | AB27: 105 | AC27: 85 | AD27: 0 | AE27: =IF(R27="","",IF(R27>=Control!$D$4,"Y","N")) -> N | AF27: =IF(S27="","",IF(M27>=Control!$D$5,"Y","N")) -> Y | AG27: =IF(T27="","",IF(AB27<=Control!$D$10,"Y","N")) -> Y | AI27: =IF(X27="","",IF(X27>=Control!$D$9,"Y","N")) -> N | AK27: =IFERROR(INDEX(Assumptions!$D$92:$D$115,MATCH(C27,Assumptions!$B$92:$B$115,0)),"Low") -> Low
